Workbook
Name DD_SOUID241686: 'HVIDE SANDE'!$A$1:$A$5012
Name DD_SOUID241803: 'BLAVANDSHUK FYR'!$A$1:$A$5013
Name DD_SOUID241842: 'VESTER VEDSTED'!$A$1:$A$5013

Sheet BLAVANDSHUK FYR
A1: EUROPEAN CLIMATE ASSESSMENT & DATASET (ECA&D) | B1: Training data: (t=01.03) | C1: DATE | D1: FG | F1: Holdout data: | G1: DATE | H1: FG | AI1: Holdout data:
A2: DENMARK, BLAVANDSHUK FYR (25239) - WIND DIRECTION | C2: 20110103 | D2: 320 | G2: 20190101 | H2: 248 | N2: =AVERAGE(O2:O2068) -> 47.839303 | O2: {=ABS(_xlfn.ANCHORARRAY(P2))} -> 56 | P2: {=H3:H2068-'HVIDE SANDE'!H2:H2067} -> 56
C3: 20110104 | D3: 269 | G3: 20190102 | H3: 309 | O3: 34 | P3: 34
A4: Klein Tank, A.M.G. and Coauthors, 2002. Daily dataset of 20th-century surface | C4: 20110105 | D4: 209 | G4: 20190103 | H4: 348 | O4: 6 | P4: -6
A5: air temperature and precipitation series for the European Climate Assessment. | C5: 20110106 | D5: 174 | G5: 20190104 | H5: 338 | O5: 11 | P5: -11
A6: Int. J. of Climatol., 22, 1441-1453. | C6: 20110107 | D6: 192 | G6: 20190105 | H6: 317 | O6: 16 | P6: 16
A7: quelle | C7: 20110108 | D7: 194 | G7: 20190106 | H7: 337 | O7: 24 | P7: -24
C8: 20110109 | D8: 163 | G8: 20190107 | H8: 316 | O8: 55 | P8: -55
C9: 20110110 | D9: 218 | G9: 20190108 | H9: 267 | O9: 59 | P9: 59
C10: 20110111 | D10: 197 | G10: 20190109 | H10: 331 | O10: 337 | P10: -337
C11: 20110112 | D11: 147 | G11: 20190110 | H11: 8 | O11: 265 | P11: 265
C12: 20110113 | D12: 240 | G12: 20190111 | H12: 272 | O12: 30 | P12: 30
A13: 15-22 DATE : Date YYYYMMDD | C13: 20110114 | D13: 129 | G13: 20190112 | H13: 315 | O13: 33 | P13: -33
A14: 24-28 DD : wind direction in degrees | C14: 20110115 | D14: 200 | G14: 20190113 | H14: 288 | O14: 3 | P14: -3
C15: 20110116 | D15: 214 | G15: 20190114 | H15: 293 | O15: 27 | P15: 27
C16: 20110117 | D16: 211 | G16: 20190115 | H16: 326 | O16: 55 | P16: -55
C17: 20110118 | D17: 208 | G17: 20190116 | H17: 275 | O17: 39 | P17: -39
C18: 20110119 | D18: 270 | G18: 20190117 | H18: 242 | O18: 75 | P18: 75
C19: 20110120 | D19: 306 | G19: 20190118 | H19: 320 | O19: 26 | P19: -26
C20: 20110121 | D20: 348 | G20: 20190119 | H20: 311 | O20: 104 | P20: -104
C21: 20110122 | D21: 304 | G21: 20190120 | H21: 211 | O21: 6 | P21: -6
C22: 20110123 | D22: 330 | G22: 20190121 | H22: 221 | O22: 67 | P22: 67
C23: 20110124 | D23: 336 | G23: 20190122 | H23: 276 | O23: 133 | P23: -133
C24: 20110125 | D24: 290 | G24: 20190123 | H24: 156 | O24: 31 | P24: -31
C25: 20110126 | D25: 335 | G25: 20190124 | H25: 126 | O25: 23 | P25: -23
C26: 20110127 | D26: 34 | G26: 20190125 | H26: 123 | O26: 1 | P26: -1
... C2067: 20160829 | D2067: 159 | G2067: 20240827 | H2067: 228 | O2067: 7 | P2067: -7
C2068: 20160830 | D2068: 313 | G2068: 20240828 | H2068: 189
C2069: 20160831 | D2069: 264 | G2069: 20240829 | H2069: 121
C2070: 20160901 | D2070: 211
C2071: 20160902 | D2071: 276
C2072: 20160903 | D2072: 244
C2073: 20160904 | D2073: 263
C2074: 20160905 | D2074: 100
C2075: 20160906 | D2075: 29
C2076: 20160907 | D2076: 193
C2077: 20160908 | D2077: 194
C2078: 20160909 | D2078: 142
C2079: 20160910 | D2079: 245
C2080: 20160911 | D2080: 183
...

Sheet HVIDE SANDE
A1: EUROPEAN CLIMATE ASSESSMENT & DATASET (ECA&D) | B1: Training data: (t-1=01.03) | C1: DATE | D1: FG | F1: Holdout data: | G1: DATE | H1: FG | J1: Predicted data based on H: | M1: Intercept | N1: 95.728423 | P1: Difference between B&H data | AI1: Holdout data:
A2: DENMARK, HVIDE SANDE (22745) - WIND DIRECTION | C2: 20110102 | D2: 324 | G2: 20190101 | H2: 253 | J2: =$N$1+H2*$N$2 -> 226.56334 | M2: X Variable 1 | N2: 0.51713406 | P2: {='BLAVANDSHUK FYR'!H2:H2068-'HVIDE SANDE'!J2:J2068} -> 21.436659 | Q2: {=ABS(_xlfn.ANCHORARRAY(P2))} -> 21.436659
C3: 20110103 | D3: 333 | G3: 20190102 | H3: 314 | J3: =$N$1+H3*$N$2 -> 258.10852 | P3: 50.891482 | Q3: 50.891482 | R3: Average: | S3: =AVERAGE(_xlfn.ANCHORARRAY(Q2)) -> 49.532917
A4: Klein Tank, A.M.G. and Coauthors, 2002. Daily dataset of 20th-century surface | C4: 20110104 | D4: 270 | G4: 20190103 | H4: 344 | J4: =$N$1+H4*$N$2 -> 273.62254 | P4: 74.37746 | Q4: 74.37746
A5: air temperature and precipitation series for the European Climate Assessment. | C5: 20110105 | D5: 211 | G5: 20190104 | H5: 328 | J5: =$N$1+H5*$N$2 -> 265.3484 | P5: 72.651605 | Q5: 72.651605
A6: Int. J. of Climatol., 22, 1441-1453. | C6: 20110106 | D6: 187 | G6: 20190105 | H6: 321 | J6: =$N$1+H6*$N$2 -> 261.72846 | P6: 55.271543 | Q6: 55.271543
A7: quelle | C7: 20110107 | D7: 202 | G7: 20190106 | H7: 340 | J7: =$N$1+H7*$N$2 -> 271.554 | P7: 65.445996 | Q7: 65.445996
C8: 20110108 | D8: 215 | G8: 20190107 | H8: 322 | J8: =$N$1+H8*$N$2 -> 262.24559 | P8: 53.754409 | Q8: 53.754409
C9: 20110109 | D9: 181 | G9: 20190108 | H9: 272 | J9: =$N$1+H9*$N$2 -> 236.38889 | P9: 30.611112 | Q9: 30.611112
C10: 20110110 | D10: 226 | G10: 20190109 | H10: 345 | J10: =$N$1+H10*$N$2 -> 274.13967 | P10: 56.860326 | Q10: 56.860326
C11: 20110111 | D11: 213 | G11: 20190110 | H11: 7 | J11: =$N$1+H11*$N$2 -> 99.348362 | P11: -91.348362 | Q11: 91.348362
C12: 20110112 | D12: 160 | G12: 20190111 | H12: 285 | J12: =$N$1+H12*$N$2 -> 243.11163 | P12: 28.888369 | Q12: 28.888369
A13: 15-22 DATE : Date YYYYMMDD | C13: 20110113 | D13: 254 | G13: 20190112 | H13: 321 | J13: =$N$1+H13*$N$2 -> 261.72846 | P13: 53.271543 | Q13: 53.271543
A14: 24-28 DD : wind direction in degrees | C14: 20110114 | D14: 137 | G14: 20190113 | H14: 296 | J14: =$N$1+H14*$N$2 -> 248.80011 | P14: 39.199895 | Q14: 39.199895
C15: 20110115 | D15: 219 | G15: 20190114 | H15: 299 | J15: =$N$1+H15*$N$2 -> 250.35151 | P15: 42.648492 | Q15: 42.648492
C16: 20110116 | D16: 225 | G16: 20190115 | H16: 330 | J16: =$N$1+H16*$N$2 -> 266.38266 | P16: 59.617337 | Q16: 59.617337
C17: 20110117 | D17: 216 | G17: 20190116 | H17: 281 | J17: =$N$1+H17*$N$2 -> 241.04309 | P17: 33.956906 | Q17: 33.956906
C18: 20110118 | D18: 223 | G18: 20190117 | H18: 245 | J18: =$N$1+H18*$N$2 -> 222.42627 | P18: 19.573732 | Q18: 19.573732
C19: 20110119 | D19: 288 | G19: 20190118 | H19: 337 | J19: =$N$1+H19*$N$2 -> 270.0026 | P19: 49.997398 | Q19: 49.997398
C20: 20110120 | D20: 323 | G20: 20190119 | H20: 315 | J20: =$N$1+H20*$N$2 -> 258.62565 | P20: 52.374348 | Q20: 52.374348
C21: 20110121 | D21: 348 | G21: 20190120 | H21: 227 | J21: =$N$1+H21*$N$2 -> 213.11786 | P21: -2.1178551 | Q21: 2.1178551
C22: 20110122 | D22: 278 | G22: 20190121 | H22: 209 | J22: =$N$1+H22*$N$2 -> 203.80944 | P22: 17.190558 | Q22: 17.190558
C23: 20110123 | D23: 340 | G23: 20190122 | H23: 289 | J23: =$N$1+H23*$N$2 -> 245.18017 | P23: 30.819833 | Q23: 30.819833
C24: 20110124 | D24: 338 | G24: 20190123 | H24: 157 | J24: =$N$1+H24*$N$2 -> 176.91847 | P24: -20.918471 | Q24: 20.918471
C25: 20110125 | D25: 299 | G25: 20190124 | H25: 146 | J25: =$N$1+H25*$N$2 -> 171.23 | P25: -45.229996 | Q25: 45.229996
C26: 20110126 | D26: 353 | G26: 20190125 | H26: 158 | J26: =$N$1+H26*$N$2 -> 177.4356 | P26: -54.435605 | Q26: 54.435605
... C2068: 20160829 | D2068: 150 | G2068: 20240829 | H2068: 139 | J2068: =$N$1+H2068*$N$2 -> 167.61006 | P2068: 21.389942 | Q2068: 21.389942
C2069: 20160830 | D2069: 309
C2070: 20160831 | D2070: 263
C2071: 20160901 | D2071: 213
C2072: 20160902 | D2072: 275
C2073: 20160903 | D2073: 239
C2074: 20160904 | D2074: 264
C2075: 20160905 | D2075: 101
C2076: 20160906 | D2076: 26
C2077: 20160907 | D2077: 191
C2078: 20160908 | D2078: 212
C2079: 20160909 | D2079: 146
C2080: 20160910 | D2080: 241
... C2921: 20181230 | D2921: 270

Sheet VESTER VEDSTED
A1: EUROPEAN CLIMATE ASSESSMENT & DATASET (ECA&D) | B1: Training data: (t-1=01.03) | C1: DATE | D1: FG | F1: Holdout data: | G1: DATE | H1: FG | J1: Predicted data based on V: | M1: Intercept | N1: 101.83667 | P1: Difference between B&V data | AI1: Holdout data:
A2: DENMARK, VESTER VEDSTED (25241) - WIND DIRECTION | C2: 20110102 | D2: 289 | G2: 20190101 | H2: 238 | J2: =$N$1+H2*$N$2 -> 222.40807 | M2: X Variable 1 | N2: 0.50660253 | P2: {='BLAVANDSHUK FYR'!H2:H2069-'VESTER VEDSTED'!J2:J2069} -> 25.591927
C3: 20110103 | D3: 294 | G3: 20190102 | H3: 295 | J3: =$N$1+H3*$N$2 -> 251.28442 | P3: 57.715582 | R3: Average: | S3: =AVERAGE(_xlfn.ANCHORARRAY(P2)) -> 2.7431676
A4: Klein Tank, A.M.G. and Coauthors, 2002. Daily dataset of 20th-century surface | C4: 20110104 | D4: 259 | G4: 20190103 | H4: 330 | J4: =$N$1+H4*$N$2 -> 269.01551 | P4: 78.984494
A5: air temperature and precipitation series for the European Climate Assessment. | C5: 20110105 | D5: 201 | G5: 20190104 | H5: 290 | J5: =$N$1+H5*$N$2 -> 248.7514 | P5: 89.248595
A6: Int. J. of Climatol., 22, 1441-1453. | C6: 20110106 | D6: 175 | G6: 20190105 | H6: 304 | J6: =$N$1+H6*$N$2 -> 255.84384 | P6: 61.15616
A7: quelle | C7: 20110107 | D7: 191 | G7: 20190106 | H7: 325 | J7: =$N$1+H7*$N$2 -> 266.48249 | P7: 70.517507
C8: 20110108 | D8: 177 | G8: 20190107 | H8: 298 | J8: =$N$1+H8*$N$2 -> 252.80423 | P8: 63.195775
C9: 20110109 | D9: 172 | G9: 20190108 | H9: 252 | J9: =$N$1+H9*$N$2 -> 229.50051 | P9: 37.499491
C10: 20110110 | D10: 208 | G10: 20190109 | H10: 317 | J10: =$N$1+H10*$N$2 -> 262.42967 | P10: 68.570327
C11: 20110111 | D11: 199 | G11: 20190110 | H11: 355 | J11: =$N$1+H11*$N$2 -> 281.68057 | P11: -273.68057
C12: 20110112 | D12: 149 | G12: 20190111 | H12: 240 | J12: =$N$1+H12*$N$2 -> 223.42128 | P12: 48.578722
A13: 15-22 DATE : Date YYYYMMDD | C13: 20110113 | D13: 234 | G13: 20190112 | H13: 300 | J13: =$N$1+H13*$N$2 -> 253.81743 | P13: 61.18257
A14: 24-28 DD : wind direction in degrees | C14: 20110114 | D14: 146 | G14: 20190113 | H14: 272 | J14: =$N$1+H14*$N$2 -> 239.63256 | P14: 48.367441
C15: 20110115 | D15: 206 | G15: 20190114 | H15: 278 | J15: =$N$1+H15*$N$2 -> 242.67217 | P15: 50.327825
C16: 20110116 | D16: 224 | G16: 20190115 | H16: 314 | J16: =$N$1+H16*$N$2 -> 260.90987 | P16: 65.090134
C17: 20110117 | D17: 209 | G17: 20190116 | H17: 264 | J17: =$N$1+H17*$N$2 -> 235.57974 | P17: 39.420261
C18: 20110118 | D18: 209 | G18: 20190117 | H18: 225 | J18: =$N$1+H18*$N$2 -> 215.82224 | P18: 26.177759
C19: 20110119 | D19: 268 | G19: 20190118 | H19: 290 | J19: =$N$1+H19*$N$2 -> 248.7514 | P19: 71.248595
C20: 20110120 | D20: 294 | G20: 20190119 | H20: 273 | J20: =$N$1+H20*$N$2 -> 240.13916 | P20: 70.860838
C21: 20110121 | D21: 353 | G21: 20190120 | H21: 162 | J21: =$N$1+H21*$N$2 -> 183.90628 | P21: 27.093719
C22: 20110122 | D22: 306 | G22: 20190121 | H22: 163 | J22: =$N$1+H22*$N$2 -> 184.41288 | P22: 36.587116
C23: 20110123 | D23: 334 | G23: 20190122 | H23: 247 | J23: =$N$1+H23*$N$2 -> 226.9675 | P23: 49.032504
C24: 20110124 | D24: 328 | G24: 20190123 | H24: 140 | J24: =$N$1+H24*$N$2 -> 172.76103 | P24: -16.761026
C25: 20110125 | D25: 289 | G25: 20190124 | H25: 106 | J25: =$N$1+H25*$N$2 -> 155.53654 | P25: -29.53654
C26: 20110126 | D26: 318 | G26: 20190125 | H26: 146 | J26: =$N$1+H26*$N$2 -> 175.80064 | P26: -52.800641
... C2069: 20160830 | D2069: 302 | G2069: 20240829 | H2069: 112 | J2069: =$N$1+H2069*$N$2 -> 158.57615 | P2069: -37.576155
C2070: 20160831 | D2070: 265
C2071: 20160901 | D2071: 202
C2072: 20160902 | D2072: 275
C2073: 20160903 | D2073: 242
C2074: 20160904 | D2074: 269
C2075: 20160905 | D2075: 103
C2076: 20160906 | D2076: 27
C2077: 20160907 | D2077: 181
C2078: 20160908 | D2078: 206
C2079: 20160909 | D2079: 136
C2080: 20160910 | D2080: 251
C2081: 20160911 | D2081: 172
... C2921: 20181230 | D2921: 247

Sheet REGRESSION
A1: SUMMARY OUTPUT | D1: B&E training data
A3: Regression Statistics
A4: Multiple R | B4: 0.51094922
A5: R Square | B5: 0.26106911
A6: Adjusted R Square | B6: 0.26081588
A7: Standard Error | B7: 77.799327
A8: Observations | B8: 2920
A10: ANOVA
B11: df | C11: SS | D11: MS | E11: F | F11: Significance F | AI11: Significance F
A12: Regression | B12: 1 | C12: 6240058.2 | D12: 6240058.2 | E12: 1030.9485 | F12: 5.6694269e-194 | AI12: 5.6694269e-194
A13: Residual | B13: 2918 | C13: 17661882 | D13: 6052.7353
A14: Total | B14: 2919 | C14: 23901940
B16: Coefficients | C16: Standard Error | D16: t Stat | E16: P-value | F16: Lower 95% | G16: Upper 95% | H16: Lower 95,0% | I16: Upper 95,0% | AI16: Lower 95% | AJ16: Upper 95,0%
A17: Intercept | B17: 96.898678 | C17: 3.5943896 | D17: 26.958313 | E17: 4.0271043e-143 | F17: 89.85088 | G17: 103.94648 | H17: 89.85088 | I17: 103.94648 | AI17: 89.85088 | AJ17: 103.94648
A18: X Variable 1 | B18: 0.53895874 | C18: 0.016785607 | D18: 32.108386 | E18: 5.6694269e-194 | F18: 0.50604591 | G18: 0.57187158 | H18: 0.50604591 | I18: 0.57187158 | AI18: 0.50604591 | AJ18: 0.57187158
A23: SUMMARY OUTPUT | D23: B&H training data
A25: Regression Statistics
A26: Multiple R | B26: 0.5070549
A27: R Square | B27: 0.25710467
A28: Adjusted R Square | B28: 0.25685008
A29: Standard Error | B29: 78.007749
A30: Observations | B30: 2920
A32: ANOVA
B33: df | C33: SS | D33: MS | E33: F | F33: Significance F | AI33: Significance F
A34: Regression | B34: 1 | C34: 6145300.3 | D34: 6145300.3 | E34: 1009.875 | F34: 1.4037454e-190 | AI34: 1.4037454e-190
A35: Residual | B35: 2918 | C35: 17756640 | D35: 6085.2089
A36: Total | B36: 2919 | C36: 23901940
B38: Coefficients | C38: Standard Error | D38: t Stat | E38: P-value | F38: Lower 95% | G38: Upper 95% | H38: Lower 95,0% | I38: Upper 95,0% | AI38: Lower 95% | AJ38: Upper 95,0%
A39: Intercept | B39: 95.728423 | C39: 3.6610845 | D39: 26.147559 | E39: 1.3976452e-135 | F39: 88.549852 | G39: 102.90699 | H39: 88.549852 | I39: 102.90699 | AI39: 88.549852 | AJ39: 102.90699
A40: X Variable 1 | B40: 0.51713406 | C40: 0.016273064 | D40: 31.77853 | E40: 1.4037454e-190 | F40: 0.48522621 | G40: 0.54904192 | H40: 0.48522621 | I40: 0.54904192 | AI40: 0.48522621 | AJ40: 0.54904192
A45: SUMMARY OUTPUT | D45: B&R training data
A47: Regression Statistics
A48: Multiple R | B48: 0.49818479
A49: R Square | B49: 0.24818809
A50: Adjusted R Square | B50: 0.24793044
A51: Standard Error | B51: 78.474495
A52: Observations | B52: 2920
A54: ANOVA
B55: df | C55: SS | D55: MS | E55: F | F55: Significance F | AI55: Significance F
A56: Regression | B56: 1 | C56: 5932176.7 | D56: 5932176.7 | E56: 963.28992 | F56: 5.1861769e-183 | AI56: 5.1861769e-183
...

Sheet GRAPH
B1: BLAVANDSHUK | C1: (t) | D1: ESBJERG | E1: (t-1) | F1: HVIDE | G1: (t-1) | H1: ROEMOE | I1: (t-1) | J1: VESTER | K1: (t-1) | M1: ESBJERG | AI1: HVIDE | AJ1: (t-1)
B2: DATE | C2: FG | D2: DATE | E2: FG | F2: DATE | G2: FG | H2: DATE | I2: FG | J2: DATE | K2: FG | AI2: DATE | AJ2: FG
B3: 20110103 | C3: 320 | D3: 20110102 | E3: 305 | F3: 20110102 | G3: 324 | H3: 20110202 | I3: 296 | J3: 20110102 | K3: 289 | AI3: 20110102 | AJ3: 296
B4: 20110104 | C4: 269 | D4: 20110103 | E4: 313 | F4: 20110103 | G4: 333 | H4: 20110103 | I4: 308 | J4: 20110103 | K4: 294 | AI4: 20110103 | AJ4: 308
B5: 20110105 | C5: 209 | D5: 20110104 | E5: 248 | F5: 20110104 | G5: 270 | H5: 20110104 | I5: 263 | J5: 20110104 | K5: 259 | AI5: 20110104 | AJ5: 263
B6: 20110106 | C6: 174 | D6: 20110105 | E6: 206 | F6: 20110105 | G6: 211 | H6: 20110105 | I6: 207 | J6: 20110105 | K6: 201 | AI6: 20110105 | AJ6: 207
B7: 20110107 | C7: 192 | D7: 20110106 | E7: 178 | F7: 20110106 | G7: 187 | H7: 20110106 | I7: 179 | J7: 20110106 | K7: 175 | AI7: 20110106 | AJ7: 179
B8: 20110108 | C8: 194 | D8: 20110107 | E8: 192 | F8: 20110107 | G8: 202 | H8: 20110107 | I8: 195 | J8: 20110107 | K8: 191 | AI8: 20110107 | AJ8: 195
B9: 20110109 | C9: 163 | D9: 20110108 | E9: 187 | F9: 20110108 | G9: 215 | H9: 20110108 | I9: 195 | J9: 20110108 | K9: 177 | AI9: 20110108 | AJ9: 195
B10: 20110110 | C10: 218 | D10: 20110109 | E10: 176 | F10: 20110109 | G10: 181 | H10: 20110109 | I10: 178 | J10: 20110109 | K10: 172 | AI10: 20110109 | AJ10: 178
B11: 20110111 | C11: 197 | D11: 20110110 | E11: 222 | F11: 20110110 | G11: 226 | H11: 20110110 | I11: 222 | J11: 20110110 | K11: 208 | AI11: 20110110 | AJ11: 222
B12: 20110112 | C12: 147 | D12: 20110111 | E12: 210 | F12: 20110111 | G12: 213 | H12: 20110111 | I12: 207 | J12: 20110111 | K12: 199 | AI12: 20110111 | AJ12: 207
B13: 20110113 | C13: 240 | D13: 20110112 | E13: 158 | F13: 20110112 | G13: 160 | H13: 20110112 | I13: 157 | J13: 20110112 | K13: 149 | AI13: 20110112 | AJ13: 157
B14: 20110114 | C14: 129 | D14: 20110113 | E14: 243 | F14: 20110113 | G14: 254 | H14: 20110113 | I14: 237 | J14: 20110113 | K14: 234 | AI14: 20110113 | AJ14: 237
B15: 20110115 | C15: 200 | D15: 20110114 | E15: 142 | F15: 20110114 | G15: 137 | H15: 20110114 | I15: 148 | J15: 20110114 | K15: 146 | AI15: 20110114 | AJ15: 148
B16: 20110116 | C16: 214 | D16: 20110115 | E16: 206 | F16: 20110115 | G16: 219 | H16: 20110115 | I16: 207 | J16: 20110115 | K16: 206 | M16: HVIDE | AI16: 20110115 | AJ16: 207
B17: 20110117 | C17: 211 | D17: 20110116 | E17: 225 | F17: 20110116 | G17: 225 | H17: 20110116 | I17: 226 | J17: 20110116 | K17: 224 | AI17: 20110116 | AJ17: 226
B18: 20110118 | C18: 208 | D18: 20110117 | E18: 223 | F18: 20110117 | G18: 216 | H18: 20110117 | I18: 223 | J18: 20110117 | K18: 209 | AI18: 20110117 | AJ18: 223
B19: 20110119 | C19: 270 | D19: 20110118 | E19: 214 | F19: 20110118 | G19: 223 | H19: 20110118 | I19: 211 | J19: 20110118 | K19: 209 | AI19: 20110118 | AJ19: 211
B20: 20110120 | C20: 306 | D20: 20110119 | E20: 273 | F20: 20110119 | G20: 288 | H20: 20110119 | I20: 274 | J20: 20110119 | K20: 268 | AI20: 20110119 | AJ20: 274
B21: 20110121 | C21: 348 | D21: 20110120 | E21: 304 | F21: 20110120 | G21: 323 | H21: 20110120 | I21: 300 | J21: 20110120 | K21: 294 | AI21: 20110120 | AJ21: 300
B22: 20110122 | C22: 304 | D22: 20110121 | E22: 346 | F22: 20110121 | G22: 348 | H22: 20110121 | I22: 355 | J22: 20110121 | K22: 353 | AI22: 20110121 | AJ22: 355
B23: 20110123 | C23: 330 | D23: 20110122 | E23: 292 | F23: 20110122 | G23: 278 | H23: 20110122 | I23: 309 | J23: 20110122 | K23: 306 | AI23: 20110122 | AJ23: 309
B24: 20110124 | C24: 336 | D24: 20110123 | E24: 338 | F24: 20110123 | G24: 340 | H24: 20110123 | I24: 334 | J24: 20110123 | K24: 334 | AI24: 20110123 | AJ24: 334
B25: 20110125 | C25: 290 | D25: 20110124 | E25: 324 | F25: 20110124 | G25: 338 | H25: 20110124 | I25: 322 | J25: 20110124 | AI25: 20110124 | AJ25: 322
B26: 20110126 | C26: 335 | D26: 20110125 | E26: 294 | F26: 20110125 | G26: 299 | H26: 20110125 | I26: 283 | J26: 20110125 | K26: 289 | AI26: 20110125 | AJ26: 283
B27: 20110127 | C27: 34 | D27: 20110126 | E27: 334 | F27: 20110126 | G27: 353 | H27: 20110126 | I27: 321 | J27: 20110126 | K27: 318 | AI27: 20110126 | AJ27: 321
B28: 20110128 | C28: 36 | D28: 20110127 | E28: 38 | F28: 20110127 | G28: 45 | H28: 20110127 | I28: 42 | J28: 20110127 | K28: 27 | AI28: 20110127 | AJ28: 42
B29: 20110129 | C29: 215 | D29: 20110128 | E29: 10 | F29: 20110128 | G29: 257 | H29: 20110128 | I29: 29 | J29: 20110128 | K29: 15 | AI29: 20110128 | AJ29: 29
B30: 20110130 | C30: 256 | D30: 20110129 | E30: 206 | F30: 20110129 | G30: 236 | H30: 20110129 | I30: 210 | J30: 20110129 | K30: 188 | AI30: 20110129 | AJ30: 210
B31: 20110131 | C31: 231 | D31: 20110130 | E31: 252 | F31: 20110130 | G31: 276 | H31: 20110130 | I31: 243 | J31: 20110130 | K31: 228 | M31: ROEMOE | AI31: 20110130 | AJ31: 243
B32: 20110201 | C32: 218 | D32: 20110131 | E32: 221 | F32: 20110131 | G32: 229 | H32: 20110131 | I32: 196 | J32: 20110131 | K32: 233 | AI32: 20110131 | AJ32: 196
B33: 20110202 | C33: 235 | D33: 20110201 | E33: 215 | F33: 20110201 | G33: 224 | H33: 20110201 | I33: 216 | J33: 20110201 | K33: 210 | AI33: 20110201 | AJ33: 216
B34: 20110203 | C34: 230 | D34: 20110202 | E34: 232 | F34: 20110202 | G34: 244 | H34: 20110202 | I34: 229 | J34: 20110202 | K34: 220 | AI34: 20110202 | AJ34: 229
B35: 20110204 | C35: 239 | D35: 20110203 | E35: 233 | F35: 20110203 | G35: 239 | H35: 20110203 | I35: 231 | J35: 20110203 | K35: 230 | AI35: 20110203 | AJ35: 231
B36: 20110205 | C36: 229 | D36: 20110204 | E36: 240 | F36: 20110204 | G36: 251 | H36: 20110204 | I36: 243 | J36: 20110204 | K36: 235 | AI36: 20110204 | AJ36: 243
B37: 20110206 | C37: 251 | D37: 20110205 | E37: 227 | F37: 20110205 | G37: 239 | H37: 20110205 | I37: 234 | J37: 20110205 | K37: 224 | AI37: 20110205 | AJ37: 234
B38: 20110207 | C38: 214 | D38: 20110206 | E38: 251 | F38: 20110206 | G38: 265 | H38: 20110206 | I38: 251 | J38: 20110206 | K38: 242 | AI38: 20110206 | AJ38: 251
B39: 20110208 | C39: 225 | D39: 20110207 | E39: 217 | F39: 20110207 | G39: 233 | H39: 20110207 | I39: 223 | J39: 20110207 | K39: 215 | AI39: 20110207 | AJ39: 223
B40: 20110209 | C40: 271 | D40: 20110208 | E40: 224 | F40: 20110208 | G40: 234 | H40: 20110208 | I40: 234 | J40: 20110208 | K40: 227 | AI40: 20110208 | AJ40: 234
...

Sheet MLR
A1: Training data: (t=01.03) | B1: DATE | C1: FG | D1: Holdout data: | E1: DATE | F1: FG | G1: Holdout data: | H1: DATE | I1: FG | U1: Predicted data based on R: | X1: Intercept | Y1: 17.171202 | AA1: Difference between B&R data
A2: BLAVANDSHUK FYR | B2: 20190101 | C2: 248 | D2: HVIDE SANDE | E2: 20190101 | F2: 253 | G2: VESTER VEDSTED | H2: 20190101 | I2: 238 | U2: =Y1+F2*MLR!$Y$2+$Y$3*I2 -> 243.31928 | V2: =AVERAGE(F2:F2068,I2:I2068) -> 203.56725 | X2: X Variable 1 | Y2: 0.28227463 | AA2: {='BLAVANDSHUK FYR'!H2:H2068-U2:U2068} -> 4.6807198 | AB2: {=ABS(_xlfn.ANCHORARRAY(AA2))} -> 4.6807198 | AC2: {=RADIANS(_xlfn.ANCHORARRAY(AB2))} -> #VALUE!
B3: 20190102 | C3: 309 | E3: 20190102 | F3: 314 | H3: 20190102 | I3: 295 | U3: =Y2+F3*MLR!$Y$2+$Y$3*I3 -> 280.70691 | V3: =AVERAGE(F3:F2069,I3:I2069) -> 203.54695 | X3: X Variable 2 | Y3: 0.65013697 | AA3: 28.293087 | AB3: 28.293087 | AC3: =AB3*(3.14159/180) -> 0.49380711 | AH3: {=C2:C2068-V2:V2068} -> 44.432753 | AI3: {=ABS(_xlfn.ANCHORARRAY(AH3))} -> 44.432753 | AJ3: =AVERAGE(_xlfn.ANCHORARRAY(AI3)) -> 78.301047
B4: 20190103 | C4: 348 | E4: 20190103 | F4: 344 | H4: 20190103 | I4: 330 | U4: =Y3+F4*MLR!$Y$2+$Y$3*I4 -> 312.29781 | V4: =AVERAGE(F4:F2070,I4:I2070) -> 203.49806 | AA4: 35.702193 | AB4: 35.702193 | AC4: =AB4*(3.14159/180) -> 0.62312028 | AD4: Average absolute error: | AE4: =AVERAGE(_xlfn.ANCHORARRAY(AB2)) -> 30.288255 | AH4: 105.45305 | AI4: 105.45305
B5: 20190104 | C5: 338 | E5: 20190104 | F5: 328 | H5: 20190104 | I5: 290 | U5: =Y4+F5*MLR!$Y$2+$Y$3*I5 -> 281.1258 | V5: =AVERAGE(F5:F2071,I5:I2071) -> 203.43338 | AA5: 56.874202 | AB5: 56.874202 | AC5: =AB5*(3.14159/180) -> 0.99264125 | AH5: 144.50194 | AI5: 144.50194
B6: 20190105 | C6: 317 | E6: 20190105 | F6: 321 | H6: 20190105 | I6: 304 | K6: SUMMARY OUTPUT | U6: =Y5+F6*MLR!$Y$2+$Y$3*I6 -> 288.25179 | V6: =AVERAGE(F6:F2072,I6:I2072) -> 203.38221 | AA6: 28.748207 | AB6: 28.748207 | AC6: =AB6*(3.14159/180) -> 0.50175044 | AH6: 134.56662 | AI6: 134.56662
B7: 20190106 | C7: 337 | E7: 20190106 | F7: 340 | H7: 20190106 | I7: 325 | U7: =Y6+F7*MLR!$Y$2+$Y$3*I7 -> 307.26789 | V7: =AVERAGE(F7:F2073,I7:I2073) -> 203.32929 | AA7: 29.732113 | AB7: 29.732113 | AC7: =AB7*(3.14159/180) -> 0.51892282 | AH7: 113.61779 | AI7: 113.61779
B8: 20190107 | C8: 316 | E8: 20190107 | F8: 322 | H8: 20190107 | I8: 298 | K8: Regression Statistics | U8: =Y7+F8*MLR!$Y$2+$Y$3*I8 -> 284.63325 | V8: =AVERAGE(F8:F2074,I8:I2074) -> 203.26662 | AA8: 31.366754 | AB8: 31.366754 | AC8: =AB8*(3.14159/180) -> 0.54745267 | AH8: 133.67071 | AI8: 133.67071
B9: 20190108 | C9: 267 | E9: 20190108 | F9: 272 | H9: 20190108 | I9: 252 | K9: Multiple R | L9: 0.84466515 | U9: =Y8+F9*MLR!$Y$2+$Y$3*I9 -> 240.61321 | V9: =AVERAGE(F9:F2075,I9:I2075) -> 203.21481 | AA9: 26.386786 | AB9: 26.386786 | AC9: =AB9*(3.14159/180) -> 0.46053591 | AH9: 112.73338 | AI9: 112.73338
B10: 20190109 | C10: 331 | E10: 20190109 | F10: 345 | H10: 20190109 | I10: 317 | K10: R Square | L10: 0.71345922 | U10: =Y9+F10*MLR!$Y$2+$Y$3*I10 -> 303.47816 | V10: =AVERAGE(F10:F2076,I10:I2076) -> 203.18626 | AA10: 27.521835 | AB10: 27.521835 | AC10: =AB10*(3.14159/180) -> 0.48034624 | AH10: 63.785194 | AI10: 63.785194
B11: 20190110 | C11: 8 | E11: 20190110 | F11: 7 | H11: 20190110 | I11: 355 | K11: Adjusted R Square | L11: 0.71318157 | U11: =Y10+F11*MLR!$Y$2+$Y$3*I11 -> 232.77455 | V11: =AVERAGE(F11:F2077,I11:I2077) -> 203.12415 | AA11: -224.77455 | AB11: 224.77455 | AC11: =AB11*(3.14159/180) -> 3.9230526 | AH11: 127.81374 | AI11: 127.81374
B12: 20190111 | C12: 272 | E12: 20190111 | F12: 285 | H12: 20190111 | I12: 240 | K12: Standard Error | L12: 49.438683 | U12: =Y11+F12*MLR!$Y$2+$Y$3*I12 -> 236.48114 | V12: =AVERAGE(F12:F2078,I12:I2078) -> 203.13491 | AA12: 35.518859 | AB12: 35.518859 | AC12: =AB12*(3.14159/180) -> 0.61992052 | AH12: -195.12415 | AI12: 195.12415
B13: 20190112 | C13: 315 | E13: 20190112 | F13: 321 | H13: 20190112 | I13: 300 | K13: Observations | L13: 2067 | U13: =Y12+F13*MLR!$Y$2+$Y$3*I13 -> 285.65125 | V13: =AVERAGE(F13:F2079,I13:I2079) -> 203.10603 | AA13: 29.348755 | AB13: 29.348755 | AC13: =AB13*(3.14159/180) -> 0.51223197 | AH13: 68.865095 | AI13: 68.865095
B14: 20190113 | C14: 288 | E14: 20190113 | F14: 296 | H14: 20190113 | I14: 272 | U14: =Y13+F14*MLR!$Y$2+$Y$3*I14 -> 260.39054 | V14: =AVERAGE(F14:F2080,I14:I2080) -> 203.05377 | AA14: 27.609456 | AB14: 27.609456 | AC14: =AB14*(3.14159/180) -> 0.4818755 | AH14: 111.89397 | AI14: 111.89397
B15: 20190114 | C15: 293 | E15: 20190114 | F15: 299 | H15: 20190114 | I15: 278 | K15: ANOVA | U15: =Y14+F15*MLR!$Y$2+$Y$3*I15 -> 265.13819 | V15: =AVERAGE(F15:F2081,I15:I2081) -> 203.01436 | AA15: 27.86181 | AB15: 27.86181 | AC15: =AB15*(3.14159/180) -> 0.48627991 | AH15: 84.946229 | AI15: 84.946229
B16: 20190115 | C16: 326 | E16: 20190115 | F16: 330 | H16: 20190115 | I16: 314 | L16: df | M16: SS | N16: MS | O16: F | P16: Significance F | U16: =Y15+F16*MLR!$Y$2+$Y$3*I16 -> 297.29363 | V16: =AVERAGE(F16:F2082,I16:I2082) -> 202.97272 | AA16: 28.706366 | AB16: 28.706366 | AC16: =AB16*(3.14159/180) -> 0.50102017 | AH16: 89.985638 | AI16: 89.985638
B17: 20190116 | C17: 275 | E17: 20190116 | F17: 281 | H17: 20190116 | I17: 264 | K17: Regression | L17: 2 | M17: 12561057 | N17: 6280528.7 | O17: 2569.5816 | P17: 0 | U17: =Y16+F17*MLR!$Y$2+$Y$3*I17 -> 250.95533 | V17: =AVERAGE(F17:F2083,I17:I2083) -> 202.91472 | AA17: 24.044671 | AB17: 24.044671 | AC17: =AB17*(3.14159/180) -> 0.41965832 | AH17: 123.02728 | AI17: 123.02728
B18: 20190117 | C18: 242 | E18: 20190117 | F18: 245 | H18: 20190117 | I18: 225 | K18: Residual | L18: 2064 | M18: 5044794.5 | N18: 2444.1834 | U18: =Y17+F18*MLR!$Y$2+$Y$3*I18 -> 215.4381 | V18: =AVERAGE(F18:F2084,I18:I2084) -> 202.88079 | AA18: 26.561899 | AB18: 26.561899 | AC18: =AB18*(3.14159/180) -> 0.4635922 | AH18: 72.085283 | AI18: 72.085283
B19: 20190118 | C19: 320 | E19: 20190118 | F19: 337 | H19: 20190118 | I19: 290 | K19: Total | L19: 2066 | M19: 17605852 | U19: =Y18+F19*MLR!$Y$2+$Y$3*I19 -> 283.66627 | V19: =AVERAGE(F19:F2085,I19:I2085) -> 202.86512 | AA19: 36.33373 | AB19: 36.33373 | AC19: =AB19*(3.14159/180) -> 0.63414269 | AH19: 39.11921 | AI19: 39.11921
B20: 20190119 | C20: 311 | E20: 20190119 | F20: 315 | H20: 20190119 | I20: 273 | U20: =Y19+F20*MLR!$Y$2+$Y$3*I20 -> 266.4039 | V20: =AVERAGE(F20:F2086,I20:I2086) -> 202.81113 | AA20: 44.596101 | AB20: 44.596101 | AC20: =AB20*(3.14159/180) -> 0.77834813 | AH20: 117.13488 | AI20: 117.13488
B21: 20190120 | C21: 211 | E21: 20190120 | F21: 227 | H21: 20190120 | I21: 162 | L21: Coefficients | M21: Standard Error | N21: t Stat | O21: P-value | P21: Lower 95% | Q21: Upper 95% | R21: Lower 95,0% | S21: Upper 95,0% | U21: =Y20+F21*MLR!$Y$2+$Y$3*I21 -> 169.39853 | V21: =AVERAGE(F21:F2087,I21:I2087) -> 202.7666 | AA21: 41.601471 | AB21: 41.601471 | AC21: =AB21*(3.14159/180) -> 0.72608203 | AH21: 108.18887 | AI21: 108.18887
B22: 20190121 | C22: 221 | E22: 20190121 | F22: 209 | H22: 20190121 | I22: 163 | K22: Intercept | L22: 17.171202 | M22: 2.8757345 | N22: 5.9710664 | O22: 2.7679504e-09 | P22: 11.531558 | Q22: 22.810845 | R22: 11.531558 | S22: 22.810845 | U22: =Y21+F22*MLR!$Y$2+$Y$3*I22 -> 164.96772 | V22: =AVERAGE(F22:F2088,I22:I2088) -> 202.77064 | AA22: 56.032277 | AB22: 56.032277 | AC22: =AB22*(3.14159/180) -> 0.9779469 | AH22: 8.2333984 | AI22: 8.2333984
B23: 20190122 | C23: 276 | E23: 20190122 | F23: 289 | H23: 20190122 | I23: 247 | K23: X Variable H | L23: 0.28227463 | M23: 0.01639955 | N23: 17.21234 | O23: 3.7903419e-62 | P23: 0.25011324 | Q23: 0.31443601 | R23: 0.25011324 | S23: 0.31443601 | U23: =Y22+F23*MLR!$Y$2+$Y$3*I23 -> 242.1612 | V23: =AVERAGE(F23:F2089,I23:I2089) -> 202.77884 | AA23: 33.838802 | AB23: 33.838802 | AC23: =AB23*(3.14159/180) -> 0.59059801 | AH23: 18.22936 | AI23: 18.22936
B24: 20190123 | C24: 156 | E24: 20190123 | F24: 157 | H24: 20190123 | I24: 140 | K24: X Variable V | L24: 0.65013697 | M24: 0.017021495 | N24: 38.195056 | O24: 6.603073e-242 | P24: 0.61675587 | Q24: 0.68351806 | R24: 0.61675587 | S24: 0.68351806 | U24: =Y23+F24*MLR!$Y$2+$Y$3*I24 -> 135.33629 | V24: =AVERAGE(F24:F2090,I24:I2090) -> 202.74694 | AA24: 20.663708 | AB24: 20.663708 | AC24: =AB24*(3.14159/180) -> 0.36064944 | AH24: 73.221163 | AI24: 73.221163
B25: 20190124 | C25: 126 | E25: 20190124 | F25: 146 | H25: 20190124 | I25: 106 | U25: =Y24+F25*MLR!$Y$2+$Y$3*I25 -> 110.12661 | V25: =AVERAGE(F25:F2091,I25:I2091) -> 202.77348 | AA25: 15.873386 | AB25: 15.873386 | AC25: =AB25*(3.14159/180) -> 0.27704262 | AH25: -46.746944 | AI25: 46.746944
B26: 20190125 | C26: 123 | E26: 20190125 | F26: 158 | H26: 20190125 | I26: 146 | U26: =Y25+F26*MLR!$Y$2+$Y$3*I26 -> 139.51939 | V26: =AVERAGE(F26:F2092,I26:I2092) -> 202.81106 | AA26: -16.519388 | AB26: 16.519388 | AC26: =AB26*(3.14159/180) -> 0.28831747 | AH26: -76.773483 | AI26: 76.773483
B27: 20190126 | C27: 157 | E27: 20190126 | F27: 163 | H27: 20190126 | I27: 152 | U27: =Y26+F27*MLR!$Y$2+$Y$3*I27 -> 144.83158 | V27: =AVERAGE(F27:F2093,I27:I2093) -> 202.83595 | AA27: 12.168417 | AB27: 12.168417 | AC27: =AB27*(3.14159/180) -> 0.21237876 | AH27: -79.811062 | AI27: 79.811062
B28: 20190127 | C28: 198 | E28: 20190127 | F28: 193 | H28: 20190127 | I28: 182 | U28: =Y27+F28*MLR!$Y$2+$Y$3*I28 -> 172.80393 | V28: =AVERAGE(F28:F2094,I28:I2094) -> 202.85816 | AA28: 25.196069 | AB28: 25.196069 | AC28: =AB28*(3.14159/180) -> 0.43975399 | AH28: -45.835945 | AI28: 45.835945
B29: 20190128 | C29: 161 | E29: 20190128 | F29: 125 | H29: 20190128 | I29: 169 | U29: =Y28+F29*MLR!$Y$2+$Y$3*I29 -> 145.15748 | V29: =AVERAGE(F29:F2095,I29:I2095) -> 202.86569 | AA29: 15.842524 | AB29: 15.842524 | AC29: =AB29*(3.14159/180) -> 0.27650398 | AH29: -4.8581578 | AI29: 4.8581578
B30: 20190129 | C30: 332 | E30: 20190129 | F30: 2 | H30: 20190129 | I30: 290 | U30: =Y29+F30*MLR!$Y$2+$Y$3*I30 -> 189.10427 | V30: =AVERAGE(F30:F2096,I30:I2096) -> 202.89308 | AA30: 142.89573 | AB30: 142.89573 | AC30: =AB30*(3.14159/180) -> 2.4939989 | AH30: -41.865686 | AI30: 41.865686
B31: 20190130 | C31: 233 | E31: 20190130 | F31: 225 | H31: 20190130 | I31: 210 | U31: =Y30+F31*MLR!$Y$2+$Y$3*I31 -> 200.04055 | V31: =AVERAGE(F31:F2097,I31:I2097) -> 202.921 | AA31: 32.959446 | AB31: 32.959446 | AC31: =AB31*(3.14159/180) -> 0.57525037 | AH31: 129.10692 | AI31: 129.10692
B32: 20190131 | C32: 124 | E32: 20190131 | F32: 131 | H32: 20190131 | I32: 111 | U32: =Y31+F32*MLR!$Y$2+$Y$3*I32 -> 109.14318 | V32: =AVERAGE(F32:F2098,I32:I2098) -> 202.91384 | AA32: 14.856821 | AB32: 14.856821 | AC32: =AB32*(3.14159/180) -> 0.25930022 | AH32: 30.078999 | AI32: 30.078999
B33: 20190201 | C33: 123 | E33: 20190201 | F33: 128 | H33: 20190201 | I33: 117 | U33: =Y32+F33*MLR!$Y$2+$Y$3*I33 -> 112.19718 | V33: =AVERAGE(F33:F2099,I33:I2099) -> 202.95408 | AA33: 10.802823 | AB33: 10.802823 | AC33: =AB33*(3.14159/180) -> 0.18854467 | AH33: -78.913844 | AI33: 78.913844
B34: 20190202 | C34: 80 | E34: 20190202 | F34: 80 | H34: 20190202 | I34: 75 | U34: =Y33+F34*MLR!$Y$2+$Y$3*I34 -> 71.342243 | V34: =AVERAGE(F34:F2100,I34:I2100) -> 202.99361 | AA34: 8.6577574 | AB34: 8.6577574 | AC34: =AB34*(3.14159/180) -> 0.15110624 | AH34: -79.954077 | AI34: 79.954077
B35: 20190203 | C35: 27 | E35: 20190203 | F35: 20 | H35: 20190203 | I35: 18 | U35: =Y34+F35*MLR!$Y$2+$Y$3*I35 -> 17.347958 | V35: =AVERAGE(F35:F2101,I35:I2101) -> 203.05531 | AA35: 9.6520421 | AB35: 9.6520421 | AC35: =AB35*(3.14159/180) -> 0.16845977 | AH35: -122.99361 | AI35: 122.99361
B36: 20190204 | C36: 304 | E36: 20190204 | F36: 305 | H36: 20190204 | I36: 279 | U36: =Y35+F36*MLR!$Y$2+$Y$3*I36 -> 267.48197 | V36: =AVERAGE(F36:F2102,I36:I2102) -> 203.14584 | AA36: 36.518025 | AB36: 36.518025 | AC36: =AB36*(3.14159/180) -> 0.63735924 | AH36: -176.05531 | AI36: 176.05531
... B2068: 20240828 | C2068: 189 | E2068: 20240829 | F2068: 139 | H2068: 20240828 | I2068: 173 | U2068: =Y2067+F2068*MLR!$Y$2+$Y$3*I2068 -> 151.70987 | V2068: =AVERAGE(F2068:F4134,I2068:I4134) -> 156 | AA2068: 37.290132 | AB2068: 37.290132 | AC2068: =AB2068*(3.14159/180) -> 0.65083503 | AH2068: 48.5 | AI2068: 48.5
AH2069: 33 | AI2069: 33
